<?xml version="1.0" ?>
<robot name="wooden_case">
  <joint name="wooden_case__lid_hinge" type="revolute">
    <parent link="wooden_case__base"/>
    <child link="wooden_case__lid"/>
    <origin xyz="0.06597 0      0.02857" rpy="0 0 0"/>
    <axis xyz="0 1 0"/>
    <limit lower="-1.5707963267948966" upper="0.5235987755982988" effort="0.0" velocity="0.0"/>
  </joint>
  <link name="wooden_case__base">
    <inertial>
      <mass value="3.9626366887499986"/>
      <origin xyz="-0.02218  0       0.17159" rpy="0 0 0"/>
      <inertia ixx="0.2135364168029657" ixy="0.0" ixz="0.0007793770806417083" iyy="0.07089428398599372" iyz="0.0" izz="0.15460392299497075"/>
    </inertial>
    <collision name="wooden_case__collision_back">
      <origin xyz="-0.05397  0       0.2018" rpy="0 0 0"/>
      <geometry>
        <box size="0.019049999999999997 0.5460999999999999 0.3175"/>
      </geometry>
    </collision>
    <collision name="wooden_case__collision_bottom">
      <origin xyz="0      0      0.03352" rpy="0 0 0"/>
      <geometry>
        <box size="0.127 0.5841999999999999 0.019049999999999997"/>
      </geometry>
    </collision>
    <collision name="wooden_case__collision_top">
      <origin xyz="0      0      0.37007" rpy="0 0 0"/>
      <geometry>
        <box size="0.127 0.5841999999999999 0.019049999999999997"/>
      </geometry>
    </collision>
    <collision name="wooden_case__collision_left">
      <origin xyz="0      -0.28257  0.2018" rpy="0 0 0"/>
      <geometry>
        <box size="0.127 0.019049999999999997 0.3175"/>
      </geometry>
    </collision>
    <collision name="wooden_case__collision_right">
      <origin xyz="0      0.28257 0.2018" rpy="0 0 0"/>
      <geometry>
        <box size="0.127 0.019049999999999997 0.3175"/>
      </geometry>
    </collision>
    <collision name="wooden_case__collision_block_left">
      <origin xyz="0.0095 -0.2151  0.012" rpy="0 0 0"/>
      <geometry>
        <box size="0.108 0.05 0.024"/>
      </geometry>
    </collision>
    <collision name="wooden_case__collision_block_right">
      <origin xyz="0.0095 0.2151 0.012" rpy="0 0 0"/>
      <geometry>
        <box size="0.108 0.05 0.024"/>
      </geometry>
    </collision>
    <visual name="wooden_case__visual_back">
      <origin xyz="-0.05397  0       0.2018" rpy="0 0 0"/>
      <geometry>
        <box size="0.019049999999999997 0.5460999999999999 0.3175"/>
      </geometry>
    </visual>
    <visual name="wooden_case__visual_bottom">
      <origin xyz="0      0      0.03352" rpy="0 0 0"/>
      <geometry>
        <box size="0.127 0.5841999999999999 0.019049999999999997"/>
      </geometry>
    </visual>
    <visual name="wooden_case__visual_top">
      <origin xyz="0      0      0.37007" rpy="0 0 0"/>
      <geometry>
        <box size="0.127 0.5841999999999999 0.019049999999999997"/>
      </geometry>
    </visual>
    <visual name="wooden_case__visual_left">
      <origin xyz="0      -0.28257  0.2018" rpy="0 0 0"/>
      <geometry>
        <box size="0.127 0.019049999999999997 0.3175"/>
      </geometry>
    </visual>
    <visual name="wooden_case__visual_right">
      <origin xyz="0      0.28257 0.2018" rpy="0 0 0"/>
      <geometry>
        <box size="0.127 0.019049999999999997 0.3175"/>
      </geometry>
    </visual>
    <visual name="wooden_case__visual_block_left">
      <origin xyz="0.0095 -0.2151  0.012" rpy="0 0 0"/>
      <geometry>
        <box size="0.108 0.05 0.024"/>
      </geometry>
    </visual>
    <visual name="wooden_case__visual_block_right">
      <origin xyz="0.0095 0.2151 0.012" rpy="0 0 0"/>
      <geometry>
        <box size="0.108 0.05 0.024"/>
      </geometry>
    </visual>
  </link>
  <link name="wooden_case__lid">
    <inertial>
      <mass value="1.9787379779999992"/>
      <origin xyz="0 0 0" rpy="0 0 0"/>
      <inertia ixx="0.05633673842708405" ixy="0" ixz="0" iyy="0.020911016446734258" iyz="0" izz="0.07712807338064145"/>
    </inertial>
    <collision name="wooden_case__collision">
      <origin xyz="0.1778   0      -0.01905" rpy="0 0 0"/>
      <geometry>
        <box size="0.35559999999999997 0.5841999999999999 0.019049999999999997"/>
      </geometry>
    </collision>
    <visual name="wooden_case__visual">
      <origin xyz="0.1778   0      -0.01905" rpy="0 0 0"/>
      <geometry>
        <box size="0.35559999999999997 0.5841999999999999 0.019049999999999997"/>
      </geometry>
    </visual>
    <visual name="wooden_case__tee_nut_1">
      <origin xyz="0.2998  -0.216   -0.01905" rpy="0 0 0"/>
      <geometry>
        <cylinder radius="0.00635" length="0.019240499999999997"/>
      </geometry>
    </visual>
    <visual name="wooden_case__tee_nut_2">
      <origin xyz="0.2998  -0.088   -0.01905" rpy="0 0 0"/>
      <geometry>
        <cylinder radius="0.00635" length="0.019240499999999997"/>
      </geometry>
    </visual>
    <visual name="wooden_case__tee_nut_3">
      <origin xyz="0.2998   0.088   -0.01905" rpy="0 0 0"/>
      <geometry>
        <cylinder radius="0.00635" length="0.019240499999999997"/>
      </geometry>
    </visual>
    <visual name="wooden_case__tee_nut_4">
      <origin xyz="0.2998   0.216   -0.01905" rpy="0 0 0"/>
      <geometry>
        <cylinder radius="0.00635" length="0.019240499999999997"/>
      </geometry>
    </visual>
  </link>
</robot>
